<?xml version="1.0"?>
<robot name="robot">

  <material name="green">
    <color rgba="0 0.5 0 1"/>
  </material>
  <material name="blue">
    <color rgba="0 0 0.5 1"/>
  </material>

  <link name="base_footprint"/>
  <link name="base_link">
    <visual>
      <geometry>
        <box size="0.1 0.16 0.2"/>
      </geometry>
      <origin xyz="0 0 0.1" rpy="0 0 0"/>
      <material name="green"/>
    </visual>
  </link>

  <link name="LF">
    <visual>
      <geometry>
        <cylinder radius="0.044" length="0.05"/>
      </geometry>
      <origin xyz="0 0 0" rpy="0 0 0"/>
    </visual>
  </link>

  <link name="LB">
    <visual>
      <geometry>
        <cylinder radius="0.044" length="0.05"/>
      </geometry>
      <origin xyz="0 0 0" rpy="0 0 0"/>
    </visual>
  </link>

  <joint name="base_dummy_joint" type="fixed">
    <parent link="base_footprint"/>
    <child link="base_link"/>
    <origin xyz="0 0 0.044" rpy="0 0 0"/>
  </joint>

  <joint name="base_LF" type="continuous">
    <parent link="base_link"/>
    <child link="LF"/>
    <origin xyz="0.0475 0.077 0" rpy="1.5708 0 0"/>
    <axis xyz="0 0 1"/>
  </joint>

  <joint name="base_LB" type="continuous">
    <parent link="base_link"/>
    <child link="LB"/>
    <origin xyz="-0.0475 0.077 0" rpy="1.5708 0 0"/>
    <axis xyz="0 0 1"/>
  </joint>

  <link name="RF">
    <visual>
      <geometry>
        <cylinder radius="0.044" length="0.05"/>
      </geometry>
      <origin xyz="0 0 0" rpy="0 0 0"/>
      <material name="blue"/>
    </visual>
  </link>

  <link name="RB">
    <visual>
      <geometry>
        <cylinder radius="0.044" length="0.05"/>
      </geometry>
      <origin xyz="0 0 0" rpy="0 0 0"/>
      <material name="blue"/>
    </visual>
  </link>

  <joint name="base_RF" type="continuous">
    <parent link="base_link"/>
    <child link="RF"/>
    <origin xyz="0.0475 -0.077 0" rpy="1.5708 0 0"/>
    <axis xyz="0 0 1"/>
  </joint>

  <joint name="base_RB" type="continuous">
    <parent link="base_link"/>
    <child link="RB"/>
    <origin xyz="-0.0475 -0.077 0" rpy="1.5708 0 0"/>
    <axis xyz="0 0 1"/>
  </joint>

  <link name="laser_frame">
    <visual>
      <geometry>
        <cylinder radius="0.075" length="0.05"/>
      </geometry>
      <origin xyz="0 0 0" rpy="0 0 0"/>
      <material name="blue"/>
    </visual>
  </link>

  <joint name="laser_joint" type="fixed">
    <parent link="base_link"/>
    <child link="laser_frame"/>
    <origin xyz="0 0 0.2" rpy="0 0 0"/>
  </joint>

</robot>
